Workbook

Sheet config
A1: parameter | B1: value | C1: note
A2: T_SIDE | B2: 64 | C2: physical tile side (cells)
A3: CELL_BITS | B3: 2 | C3: bits per memristor cell
A4: SPARE | B4: 0.2 | C4: spare fraction for defects
A5: T_WL | B5: 2 | C5: T per WL driver
A6: T_TIA | B6: 10 | C6: T per column TIA
A7: T_TILE | B7: =B2*(B5+B6) -> 768 | C7: 64*(2+10) = 768 T / full tile
A8: T_BIAS | B8: 1 | C8: transisors per bias current source
A9: SERVO_T | B9: 20 | C9: AGC servo transistors
A10: SERVO_C | B10: 2 | C10: AGC servo capacitors
A11: SERVO_D | B11: 1 | C11: AGC servo diodes
A12: DAC_SW | B12: 8 | C12: DAC switches per lane
A13: ADC_T | B13: 10 | C13: ADC(8/12) SAR transistors per lane
A14: ADC_C | B14: 8 | C14: ADC cap-DAC caps per lane
A15: LIM_D | B15: 2 | C15: limiter diodes per lane
A16: DW_K | B16: 9 | C16: depthwise kernel taps (3x3)
A17: SUB_SQ | B17: 4 | C17: sub-T per squarer lane
A18: SUB_DIV | B18: 10 | C18: sub-T divider (Gilbert)
A19: SUB_SQRT | B19: 8 | C19: sub-T sqrt
... A27: M_PAD | B27: 16 | C27: ring depth

Sheet micronet-s
A1: MicroNet-S (Speech Commands, 12 labels) — MicroNets, ARM ML-zoo
A2: Input MFCC 49x10. 59,136 int8 GEMM weights + 3.8KB BN (digital), pw-pointwise, dw-depthwise
A4: Tensor kind | B4: Count | C4: Rows (out) | D4: Cols (in) | E4: Params
A5: conv1 10x4x1->84 s1 | B5: 1 | C5: 84 | D5: 40 | E5: =B5*C5*D5 -> 3360
A6: pw 1x1 84->112 | B6: 1 | C6: 112 | D6: 84 | E6: =B6*C6*D6 -> 9408 | I6: test run results in the sim | J6: rel_L2 error | K6: KL divergence
A7: dw 3x3 112ch | B7: 1 | C7: 112 | D7: 9 | E7: =B7*C7*D7 -> 1008 | I7: noiseless | J7: 0.0034 | K7: 0
A8: pw 1x1 112->84 | B8: 1 | C8: 84 | D8: 112 | E8: =B8*C8*D8 -> 9408 | I8: with noise | J8: 0.6715±0.2286 | K8: 0.00982±0.00563
A9: dw 3x3 84ch | B9: 4 | C9: 84 | D9: 9 | E9: =B9*C9*D9 -> 3024
A10: pw 1x1 84->84 | B10: 2 | C10: 84 | D10: 84 | E10: =B10*C10*D10 -> 14112
A11: pw 1x1 84->196 | B11: 1 | C11: 196 | D11: 84 | E11: =B11*C11*D11 -> 16464
A12: head 1x1 196->12 | B12: 1 | C12: 12 | D12: 196 | E12: =B12*C12*D12 -> 2352
A13: TOTAL | E13: =SUM(E5:E12) -> 59136
A15: WB | B15: 8
A16: slices | B16: =B15/config!$B$3 -> 4
A19: Layer | B19: Kind | C19: Rows | D19: Cols | E19: H | F19: W | G19: Tiles | H19: Params | I19: Channels | J19: Limiter | K19: Bias | L19: Transistors | M19: Subthreshold transistors | N19: Memristors | O19: Capacitors | P19: Diodes | Q19: Wiring
A20: op0 conv 10x4 s1 | B20: conv | C20: 84 | D20: 40 | E20: 49 | F20: 10 | G20: =IF(OR(B20="conv",B20="pw",B20="head",B20="mm"),-INT(-C20/config!$B$2)*-INT(-D20/config!$B$2),IF(B20="dw",1,"")) -> 2 | H20: =IF(OR(B20="conv",B20="pw",B20="head",B20="mm",B20="dw"),C20*D20,"") -> 3360 | I20: =IF(OR(B20="conv",B20="pw",B20="head",B20="mm",B20="dw",B20="pool"),C20,"") -> 84 | J20: =IF(OR(B20="conv",B20="pw",B20="mm",B20="dw"),I20*E20*F20,0) -> 41160 | K20: =IF(OR(B20="conv",B20="pw",B20="dw",B20="head"),C20,0) -> 84 | L20: =IF(B20="dw",I20*config!$B$6+config!$B$16*config!$B$5+K20+config!$B$9,IF(B20="pool",I20*2+config!$B$9,IF(B20="dac",C20*config!$B$12,IF(B20="adc",C20*config!$B$13,IF(OR(B20="conv",B20="pw"),G20*config!$B$7+K20+config!$B$9,IF(B20="head",G20*config!$B$7+K20,"")))))) -> 1640 | M20: 0 | N20: =IF(OR(B20="conv",B20="pw",B20="head",B20="mm",B20="dw"),H20*2*'micronet-s'!$B$16*(1+config!$B$4),0) -> 32256 | O20: =IF(OR(B20="conv",B20="pw",B20="dw",B20="pool"),config!$B$10,IF(B20="adc",C20*config!$B$14,0)) -> 2 | P20: =IF(OR(B20="conv",B20="pw",B20="dw",B20="pool"),J20*2+config!$B$11,0) -> 82321 | Q20: =IF(OR(B20="conv",B20="pw",B20="dw",B20="head"),G20*2*config!$B$2+I20*10,0) -> 1096
A21: op1 dw 3x3 s2 | B21: dw | C21: 84 | D21: 9 | E21: 25 | F21: 5 | G21: =IF(OR(B21="conv",B21="pw",B21="head",B21="mm"),-INT(-C21/config!$B$2)*-INT(-D21/config!$B$2),IF(B21="dw",1,"")) -> 1 | H21: =IF(OR(B21="conv",B21="pw",B21="head",B21="mm",B21="dw"),C21*D21,"") -> 756 | I21: =IF(OR(B21="conv",B21="pw",B21="head",B21="mm",B21="dw",B21="pool"),C21,"") -> 84 | J21: =IF(OR(B21="conv",B21="pw",B21="mm",B21="dw"),I21*E21*F21,0) -> 10500 | K21: =IF(OR(B21="conv",B21="pw",B21="dw",B21="head"),C21,0) -> 84 | L21: =IF(B21="dw",I21*config!$B$6+config!$B$16*config!$B$5+K21+config!$B$9,IF(B21="pool",I21*2+config!$B$9,IF(B21="dac",C21*config!$B$12,IF(B21="adc",C21*config!$B$13,IF(OR(B21="conv",B21="pw"),G21*config!$B$7+K21+config!$B$9,IF(B21="head",G21*config!$B$7+K21,"")))))) -> 962 | M21: 0 | N21: =IF(OR(B21="conv",B21="pw",B21="head",B21="mm",B21="dw"),H21*2*'micronet-s'!$B$16*(1+config!$B$4),0) -> 7257.6 | O21: =IF(OR(B21="conv",B21="pw",B21="dw",B21="pool"),config!$B$10,IF(B21="adc",C21*config!$B$14,0)) -> 2 | P21: =IF(OR(B21="conv",B21="pw",B21="dw",B21="pool"),J21*2+config!$B$11,0) -> 21001 | Q21: =IF(OR(B21="conv",B21="pw",B21="dw",B21="head"),G21*2*config!$B$2+I21*10,0) -> 968
A22: op2 pw | B22: pw | C22: 112 | D22: 84 | E22: 25 | F22: 5 | G22: =IF(OR(B22="conv",B22="pw",B22="head",B22="mm"),-INT(-C22/config!$B$2)*-INT(-D22/config!$B$2),IF(B22="dw",1,"")) -> 4 | H22: =IF(OR(B22="conv",B22="pw",B22="head",B22="mm",B22="dw"),C22*D22,"") -> 9408 | I22: =IF(OR(B22="conv",B22="pw",B22="head",B22="mm",B22="dw",B22="pool"),C22,"") -> 112 | J22: =IF(OR(B22="conv",B22="pw",B22="mm",B22="dw"),I22*E22*F22,0) -> 14000 | K22: =IF(OR(B22="conv",B22="pw",B22="dw",B22="head"),C22,0) -> 112 | L22: =IF(B22="dw",I22*config!$B$6+config!$B$16*config!$B$5+K22+config!$B$9,IF(B22="pool",I22*2+config!$B$9,IF(B22="dac",C22*config!$B$12,IF(B22="adc",C22*config!$B$13,IF(OR(B22="conv",B22="pw"),G22*config!$B$7+K22+config!$B$9,IF(B22="head",G22*config!$B$7+K22,"")))))) -> 3204 | M22: 0 | N22: =IF(OR(B22="conv",B22="pw",B22="head",B22="mm",B22="dw"),H22*2*'micronet-s'!$B$16*(1+config!$B$4),0) -> 90316.8 | O22: =IF(OR(B22="conv",B22="pw",B22="dw",B22="pool"),config!$B$10,IF(B22="adc",C22*config!$B$14,0)) -> 2 | P22: =IF(OR(B22="conv",B22="pw",B22="dw",B22="pool"),J22*2+config!$B$11,0) -> 28001 | Q22: =IF(OR(B22="conv",B22="pw",B22="dw",B22="head"),G22*2*config!$B$2+I22*10,0) -> 1632
A23: op3 dw | B23: dw | C23: 112 | D23: 9 | E23: 25 | F23: 5 | G23: =IF(OR(B23="conv",B23="pw",B23="head",B23="mm"),-INT(-C23/config!$B$2)*-INT(-D23/config!$B$2),IF(B23="dw",1,"")) -> 1 | H23: =IF(OR(B23="conv",B23="pw",B23="head",B23="mm",B23="dw"),C23*D23,"") -> 1008 | I23: =IF(OR(B23="conv",B23="pw",B23="head",B23="mm",B23="dw",B23="pool"),C23,"") -> 112 | J23: =IF(OR(B23="conv",B23="pw",B23="mm",B23="dw"),I23*E23*F23,0) -> 14000 | K23: =IF(OR(B23="conv",B23="pw",B23="dw",B23="head"),C23,0) -> 112 | L23: =IF(B23="dw",I23*config!$B$6+config!$B$16*config!$B$5+K23+config!$B$9,IF(B23="pool",I23*2+config!$B$9,IF(B23="dac",C23*config!$B$12,IF(B23="adc",C23*config!$B$13,IF(OR(B23="conv",B23="pw"),G23*config!$B$7+K23+config!$B$9,IF(B23="head",G23*config!$B$7+K23,"")))))) -> 1270 | M23: 0 | N23: =IF(OR(B23="conv",B23="pw",B23="head",B23="mm",B23="dw"),H23*2*'micronet-s'!$B$16*(1+config!$B$4),0) -> 9676.8 | O23: =IF(OR(B23="conv",B23="pw",B23="dw",B23="pool"),config!$B$10,IF(B23="adc",C23*config!$B$14,0)) -> 2 | P23: =IF(OR(B23="conv",B23="pw",B23="dw",B23="pool"),J23*2+config!$B$11,0) -> 28001 | Q23: =IF(OR(B23="conv",B23="pw",B23="dw",B23="head"),G23*2*config!$B$2+I23*10,0) -> 1248
A24: op4 pw | B24: pw | C24: 84 | D24: 112 | E24: 25 | F24: 5 | G24: =IF(OR(B24="conv",B24="pw",B24="head",B24="mm"),-INT(-C24/config!$B$2)*-INT(-D24/config!$B$2),IF(B24="dw",1,"")) -> 4 | H24: =IF(OR(B24="conv",B24="pw",B24="head",B24="mm",B24="dw"),C24*D24,"") -> 9408 | I24: =IF(OR(B24="conv",B24="pw",B24="head",B24="mm",B24="dw",B24="pool"),C24,"") -> 84 | J24: =IF(OR(B24="conv",B24="pw",B24="mm",B24="dw"),I24*E24*F24,0) -> 10500 | K24: =IF(OR(B24="conv",B24="pw",B24="dw",B24="head"),C24,0) -> 84 | L24: =IF(B24="dw",I24*config!$B$6+config!$B$16*config!$B$5+K24+config!$B$9,IF(B24="pool",I24*2+config!$B$9,IF(B24="dac",C24*config!$B$12,IF(B24="adc",C24*config!$B$13,IF(OR(B24="conv",B24="pw"),G24*config!$B$7+K24+config!$B$9,IF(B24="head",G24*config!$B$7+K24,"")))))) -> 3176 | M24: 0 | N24: =IF(OR(B24="conv",B24="pw",B24="head",B24="mm",B24="dw"),H24*2*'micronet-s'!$B$16*(1+config!$B$4),0) -> 90316.8 | O24: =IF(OR(B24="conv",B24="pw",B24="dw",B24="pool"),config!$B$10,IF(B24="adc",C24*config!$B$14,0)) -> 2 | P24: =IF(OR(B24="conv",B24="pw",B24="dw",B24="pool"),J24*2+config!$B$11,0) -> 21001 | Q24: =IF(OR(B24="conv",B24="pw",B24="dw",B24="head"),G24*2*config!$B$2+I24*10,0) -> 1352
A25: op5 dw | B25: dw | C25: 84 | D25: 9 | E25: 25 | F25: 5 | G25: =IF(OR(B25="conv",B25="pw",B25="head",B25="mm"),-INT(-C25/config!$B$2)*-INT(-D25/config!$B$2),IF(B25="dw",1,"")) -> 1 | H25: =IF(OR(B25="conv",B25="pw",B25="head",B25="mm",B25="dw"),C25*D25,"") -> 756 | I25: =IF(OR(B25="conv",B25="pw",B25="head",B25="mm",B25="dw",B25="pool"),C25,"") -> 84 | J25: =IF(OR(B25="conv",B25="pw",B25="mm",B25="dw"),I25*E25*F25,0) -> 10500 | K25: =IF(OR(B25="conv",B25="pw",B25="dw",B25="head"),C25,0) -> 84 | L25: =IF(B25="dw",I25*config!$B$6+config!$B$16*config!$B$5+K25+config!$B$9,IF(B25="pool",I25*2+config!$B$9,IF(B25="dac",C25*config!$B$12,IF(B25="adc",C25*config!$B$13,IF(OR(B25="conv",B25="pw"),G25*config!$B$7+K25+config!$B$9,IF(B25="head",G25*config!$B$7+K25,"")))))) -> 962 | M25: 0 | N25: =IF(OR(B25="conv",B25="pw",B25="head",B25="mm",B25="dw"),H25*2*'micronet-s'!$B$16*(1+config!$B$4),0) -> 7257.6 | O25: =IF(OR(B25="conv",B25="pw",B25="dw",B25="pool"),config!$B$10,IF(B25="adc",C25*config!$B$14,0)) -> 2 | P25: =IF(OR(B25="conv",B25="pw",B25="dw",B25="pool"),J25*2+config!$B$11,0) -> 21001 | Q25: =IF(OR(B25="conv",B25="pw",B25="dw",B25="head"),G25*2*config!$B$2+I25*10,0) -> 968
A26: op6 pw | B26: pw | C26: 84 | D26: 84 | E26: 25 | F26: 5 | G26: =IF(OR(B26="conv",B26="pw",B26="head",B26="mm"),-INT(-C26/config!$B$2)*-INT(-D26/config!$B$2),IF(B26="dw",1,"")) -> 4 | H26: =IF(OR(B26="conv",B26="pw",B26="head",B26="mm",B26="dw"),C26*D26,"") -> 7056 | I26: =IF(OR(B26="conv",B26="pw",B26="head",B26="mm",B26="dw",B26="pool"),C26,"") -> 84 | J26: =IF(OR(B26="conv",B26="pw",B26="mm",B26="dw"),I26*E26*F26,0) -> 10500 | K26: =IF(OR(B26="conv",B26="pw",B26="dw",B26="head"),C26,0) -> 84 | L26: =IF(B26="dw",I26*config!$B$6+config!$B$16*config!$B$5+K26+config!$B$9,IF(B26="pool",I26*2+config!$B$9,IF(B26="dac",C26*config!$B$12,IF(B26="adc",C26*config!$B$13,IF(OR(B26="conv",B26="pw"),G26*config!$B$7+K26+config!$B$9,IF(B26="head",G26*config!$B$7+K26,"")))))) -> 3176 | M26: 0 | N26: =IF(OR(B26="conv",B26="pw",B26="head",B26="mm",B26="dw"),H26*2*'micronet-s'!$B$16*(1+config!$B$4),0) -> 67737.6 | O26: =IF(OR(B26="conv",B26="pw",B26="dw",B26="pool"),config!$B$10,IF(B26="adc",C26*config!$B$14,0)) -> 2 | P26: =IF(OR(B26="conv",B26="pw",B26="dw",B26="pool"),J26*2+config!$B$11,0) -> 21001 | Q26: =IF(OR(B26="conv",B26="pw",B26="dw",B26="head"),G26*2*config!$B$2+I26*10,0) -> 1352
A27: op7 dw | B27: dw | C27: 84 | D27: 9 | E27: 25 | F27: 5 | G27: =IF(OR(B27="conv",B27="pw",B27="head",B27="mm"),-INT(-C27/config!$B$2)*-INT(-D27/config!$B$2),IF(B27="dw",1,"")) -> 1 | H27: =IF(OR(B27="conv",B27="pw",B27="head",B27="mm",B27="dw"),C27*D27,"") -> 756 | I27: =IF(OR(B27="conv",B27="pw",B27="head",B27="mm",B27="dw",B27="pool"),C27,"") -> 84 | J27: =IF(OR(B27="conv",B27="pw",B27="mm",B27="dw"),I27*E27*F27,0) -> 10500 | K27: =IF(OR(B27="conv",B27="pw",B27="dw",B27="head"),C27,0) -> 84 | L27: =IF(B27="dw",I27*config!$B$6+config!$B$16*config!$B$5+K27+config!$B$9,IF(B27="pool",I27*2+config!$B$9,IF(B27="dac",C27*config!$B$12,IF(B27="adc",C27*config!$B$13,IF(OR(B27="conv",B27="pw"),G27*config!$B$7+K27+config!$B$9,IF(B27="head",G27*config!$B$7+K27,"")))))) -> 962 | M27: 0 | N27: =IF(OR(B27="conv",B27="pw",B27="head",B27="mm",B27="dw"),H27*2*'micronet-s'!$B$16*(1+config!$B$4),0) -> 7257.6 | O27: =IF(OR(B27="conv",B27="pw",B27="dw",B27="pool"),config!$B$10,IF(B27="adc",C27*config!$B$14,0)) -> 2 | P27: =IF(OR(B27="conv",B27="pw",B27="dw",B27="pool"),J27*2+config!$B$11,0) -> 21001 | Q27: =IF(OR(B27="conv",B27="pw",B27="dw",B27="head"),G27*2*config!$B$2+I27*10,0) -> 968
A28: op8 pw | B28: pw | C28: 84 | D28: 84 | E28: 25 | F28: 5 | G28: =IF(OR(B28="conv",B28="pw",B28="head",B28="mm"),-INT(-C28/config!$B$2)*-INT(-D28/config!$B$2),IF(B28="dw",1,"")) -> 4 | H28: =IF(OR(B28="conv",B28="pw",B28="head",B28="mm",B28="dw"),C28*D28,"") -> 7056 | I28: =IF(OR(B28="conv",B28="pw",B28="head",B28="mm",B28="dw",B28="pool"),C28,"") -> 84 | J28: =IF(OR(B28="conv",B28="pw",B28="mm",B28="dw"),I28*E28*F28,0) -> 10500 | K28: =IF(OR(B28="conv",B28="pw",B28="dw",B28="head"),C28,0) -> 84 | L28: =IF(B28="dw",I28*config!$B$6+config!$B$16*config!$B$5+K28+config!$B$9,IF(B28="pool",I28*2+config!$B$9,IF(B28="dac",C28*config!$B$12,IF(B28="adc",C28*config!$B$13,IF(OR(B28="conv",B28="pw"),G28*config!$B$7+K28+config!$B$9,IF(B28="head",G28*config!$B$7+K28,"")))))) -> 3176 | M28: 0 | N28: =IF(OR(B28="conv",B28="pw",B28="head",B28="mm",B28="dw"),H28*2*'micronet-s'!$B$16*(1+config!$B$4),0) -> 67737.6 | O28: =IF(OR(B28="conv",B28="pw",B28="dw",B28="pool"),config!$B$10,IF(B28="adc",C28*config!$B$14,0)) -> 2 | P28: =IF(OR(B28="conv",B28="pw",B28="dw",B28="pool"),J28*2+config!$B$11,0) -> 21001 | Q28: =IF(OR(B28="conv",B28="pw",B28="dw",B28="head"),G28*2*config!$B$2+I28*10,0) -> 1352
A29: op9 dw | B29: dw | C29: 84 | D29: 9 | E29: 25 | F29: 5 | G29: =IF(OR(B29="conv",B29="pw",B29="head",B29="mm"),-INT(-C29/config!$B$2)*-INT(-D29/config!$B$2),IF(B29="dw",1,"")) -> 1 | H29: =IF(OR(B29="conv",B29="pw",B29="head",B29="mm",B29="dw"),C29*D29,"") -> 756 | I29: =IF(OR(B29="conv",B29="pw",B29="head",B29="mm",B29="dw",B29="pool"),C29,"") -> 84 | J29: =IF(OR(B29="conv",B29="pw",B29="mm",B29="dw"),I29*E29*F29,0) -> 10500 | K29: =IF(OR(B29="conv",B29="pw",B29="dw",B29="head"),C29,0) -> 84 | L29: =IF(B29="dw",I29*config!$B$6+config!$B$16*config!$B$5+K29+config!$B$9,IF(B29="pool",I29*2+config!$B$9,IF(B29="dac",C29*config!$B$12,IF(B29="adc",C29*config!$B$13,IF(OR(B29="conv",B29="pw"),G29*config!$B$7+K29+config!$B$9,IF(B29="head",G29*config!$B$7+K29,"")))))) -> 962 | M29: 0 | N29: =IF(OR(B29="conv",B29="pw",B29="head",B29="mm",B29="dw"),H29*2*'micronet-s'!$B$16*(1+config!$B$4),0) -> 7257.6 | O29: =IF(OR(B29="conv",B29="pw",B29="dw",B29="pool"),config!$B$10,IF(B29="adc",C29*config!$B$14,0)) -> 2 | P29: =IF(OR(B29="conv",B29="pw",B29="dw",B29="pool"),J29*2+config!$B$11,0) -> 21001 | Q29: =IF(OR(B29="conv",B29="pw",B29="dw",B29="head"),G29*2*config!$B$2+I29*10,0) -> 968
A30: op10 pw | B30: pw | C30: 196 | D30: 84 | E30: 25 | F30: 5 | G30: =IF(OR(B30="conv",B30="pw",B30="head",B30="mm"),-INT(-C30/config!$B$2)*-INT(-D30/config!$B$2),IF(B30="dw",1,"")) -> 8 | H30: =IF(OR(B30="conv",B30="pw",B30="head",B30="mm",B30="dw"),C30*D30,"") -> 16464 | I30: =IF(OR(B30="conv",B30="pw",B30="head",B30="mm",B30="dw",B30="pool"),C30,"") -> 196 | J30: =IF(OR(B30="conv",B30="pw",B30="mm",B30="dw"),I30*E30*F30,0) -> 24500 | K30: =IF(OR(B30="conv",B30="pw",B30="dw",B30="head"),C30,0) -> 196 | L30: =IF(B30="dw",I30*config!$B$6+config!$B$16*config!$B$5+K30+config!$B$9,IF(B30="pool",I30*2+config!$B$9,IF(B30="dac",C30*config!$B$12,IF(B30="adc",C30*config!$B$13,IF(OR(B30="conv",B30="pw"),G30*config!$B$7+K30+config!$B$9,IF(B30="head",G30*config!$B$7+K30,"")))))) -> 6360 | M30: 0 | N30: =IF(OR(B30="conv",B30="pw",B30="head",B30="mm",B30="dw"),H30*2*'micronet-s'!$B$16*(1+config!$B$4),0) -> 158054.4 | O30: =IF(OR(B30="conv",B30="pw",B30="dw",B30="pool"),config!$B$10,IF(B30="adc",C30*config!$B$14,0)) -> 2 | P30: =IF(OR(B30="conv",B30="pw",B30="dw",B30="pool"),J30*2+config!$B$11,0) -> 49001 | Q30: =IF(OR(B30="conv",B30="pw",B30="dw",B30="head"),G30*2*config!$B$2+I30*10,0) -> 2984
A31: AvgPool 125:1 | B31: pool | C31: 196 | E31: 1 | F31: 1 | G31: =IF(OR(B31="conv",B31="pw",B31="head",B31="mm"),-INT(-C31/config!$B$2)*-INT(-D31/config!$B$2),IF(B31="dw",1,"")) | H31: =IF(OR(B31="conv",B31="pw",B31="head",B31="mm",B31="dw"),C31*D31,"") | I31: =IF(OR(B31="conv",B31="pw",B31="head",B31="mm",B31="dw",B31="pool"),C31,"") -> 196 | J31: =IF(OR(B31="conv",B31="pw",B31="mm",B31="dw"),I31*E31*F31,0) -> 0 | K31: =IF(OR(B31="conv",B31="pw",B31="dw",B31="head"),C31,0) -> 0 | L31: =IF(B31="dw",I31*config!$B$6+config!$B$16*config!$B$5+K31+config!$B$9,IF(B31="pool",I31*2+config!$B$9,IF(B31="dac",C31*config!$B$12,IF(B31="adc",C31*config!$B$13,IF(OR(B31="conv",B31="pw"),G31*config!$B$7+K31+config!$B$9,IF(B31="head",G31*config!$B$7+K31,"")))))) -> 412 | M31: 0 | N31: =IF(OR(B31="conv",B31="pw",B31="head",B31="mm",B31="dw"),H31*2*'micronet-s'!$B$16*(1+config!$B$4),0) -> 0 | O31: =IF(OR(B31="conv",B31="pw",B31="dw",B31="pool"),config!$B$10,IF(B31="adc",C31*config!$B$14,0)) -> 2 | P31: =IF(OR(B31="conv",B31="pw",B31="dw",B31="pool"),J31*2+config!$B$11,0) -> 1 | Q31: =IF(OR(B31="conv",B31="pw",B31="dw",B31="head"),G31*2*config!$B$2+I31*10,0) -> 0
A32: head (no act) | B32: head | C32: 12 | D32: 196 | E32: 1 | F32: 1 | G32: =IF(OR(B32="conv",B32="pw",B32="head",B32="mm"),-INT(-C32/config!$B$2)*-INT(-D32/config!$B$2),IF(B32="dw",1,"")) -> 4 | H32: =IF(OR(B32="conv",B32="pw",B32="head",B32="mm",B32="dw"),C32*D32,"") -> 2352 | I32: =IF(OR(B32="conv",B32="pw",B32="head",B32="mm",B32="dw",B32="pool"),C32,"") -> 12 | J32: =IF(OR(B32="conv",B32="pw",B32="mm",B32="dw"),I32*E32*F32,0) -> 0 | K32: =IF(OR(B32="conv",B32="pw",B32="dw",B32="head"),C32,0) -> 12 | L32: =IF(B32="dw",I32*config!$B$6+config!$B$16*config!$B$5+K32+config!$B$9,IF(B32="pool",I32*2+config!$B$9,IF(B32="dac",C32*config!$B$12,IF(B32="adc",C32*config!$B$13,IF(OR(B32="conv",B32="pw"),G32*config!$B$7+K32+config!$B$9,IF(B32="head",G32*config!$B$7+K32,"")))))) -> 3084 | M32: 0 | N32: =IF(OR(B32="conv",B32="pw",B32="head",B32="mm",B32="dw"),H32*2*'micronet-s'!$B$16*(1+config!$B$4),0) -> 22579.2 | O32: =IF(OR(B32="conv",B32="pw",B32="dw",B32="pool"),config!$B$10,IF(B32="adc",C32*config!$B$14,0)) -> 0 | P32: =IF(OR(B32="conv",B32="pw",B32="dw",B32="pool"),J32*2+config!$B$11,0) -> 0 | Q32: =IF(OR(B32="conv",B32="pw",B32="dw",B32="head"),G32*2*config!$B$2+I32*10,0) -> 632
A33: DAC(8) | B33: dac | C33: 490 | G33: =IF(OR(B33="conv",B33="pw",B33="head",B33="mm"),-INT(-C33/config!$B$2)*-INT(-D33/config!$B$2),IF(B33="dw",1,"")) | H33: =IF(OR(B33="conv",B33="pw",B33="head",B33="mm",B33="dw"),C33*D33,"") | I33: =IF(OR(B33="conv",B33="pw",B33="head",B33="mm",B33="dw",B33="pool"),C33,"") | J33: =IF(OR(B33="conv",B33="pw",B33="mm",B33="dw"),I33*E33*F33,0) -> 0 | K33: =IF(OR(B33="conv",B33="pw",B33="dw",B33="head"),C33,0) -> 0 | L33: =IF(B33="dw",I33*config!$B$6+config!$B$16*config!$B$5+K33+config!$B$9,IF(B33="pool",I33*2+config!$B$9,IF(B33="dac",C33*config!$B$12,IF(B33="adc",C33*config!$B$13,IF(OR(B33="conv",B33="pw"),G33*config!$B$7+K33+config!$B$9,IF(B33="head",G33*config!$B$7+K33,"")))))) -> 3920 | M33: 0 | N33: =IF(OR(B33="conv",B33="pw",B33="head",B33="mm",B33="dw"),H33*2*'micronet-s'!$B$16*(1+config!$B$4),0) -> 0 | O33: =IF(OR(B33="conv",B33="pw",B33="dw",B33="pool"),config!$B$10,IF(B33="adc",C33*config!$B$14,0)) -> 0 | P33: =IF(OR(B33="conv",B33="pw",B33="dw",B33="pool"),J33*2+config!$B$11,0) -> 0 | Q33: =IF(OR(B33="conv",B33="pw",B33="dw",B33="head"),G33*2*config!$B$2+I33*10,0) -> 0
A34: ADC(8) | B34: adc | C34: 12 | G34: =IF(OR(B34="conv",B34="pw",B34="head",B34="mm"),-INT(-C34/config!$B$2)*-INT(-D34/config!$B$2),IF(B34="dw",1,"")) | H34: =IF(OR(B34="conv",B34="pw",B34="head",B34="mm",B34="dw"),C34*D34,"") | I34: =IF(OR(B34="conv",B34="pw",B34="head",B34="mm",B34="dw",B34="pool"),C34,"") | J34: =IF(OR(B34="conv",B34="pw",B34="mm",B34="dw"),I34*E34*F34,0) -> 0 | K34: =IF(OR(B34="conv",B34="pw",B34="dw",B34="head"),C34,0) -> 0 | L34: =IF(B34="dw",I34*config!$B$6+config!$B$16*config!$B$5+K34+config!$B$9,IF(B34="pool",I34*2+config!$B$9,IF(B34="dac",C34*config!$B$12,IF(B34="adc",C34*config!$B$13,IF(OR(B34="conv",B34="pw"),G34*config!$B$7+K34+config!$B$9,IF(B34="head",G34*config!$B$7+K34,"")))))) -> 120 | M34: 0 | N34: =IF(OR(B34="conv",B34="pw",B34="head",B34="mm",B34="dw"),H34*2*'micronet-s'!$B$16*(1+config!$B$4),0) -> 0 | O34: =IF(OR(B34="conv",B34="pw",B34="dw",B34="pool"),config!$B$10,IF(B34="adc",C34*config!$B$14,0)) -> 96 | P34: =IF(OR(B34="conv",B34="pw",B34="dw",B34="pool"),J34*2+config!$B$11,0) -> 0 | Q34: =IF(OR(B34="conv",B34="pw",B34="dw",B34="head"),G34*2*config!$B$2+I34*10,0) -> 0
A35: bus wiring | B35: bus | Q35: =SUM(J20:J34)+490+196+12 -> 167858
A36: TOTAL | G36: =SUM(G20:G35) -> 35 | H36: =SUM(H20:H35) -> 59136 | I36: =SUM(I20:I35) -> 1300 | J36: =SUM(J20:J35) -> 167160 | K36: =SUM(K20:K35) -> 1104 | L36: =SUM(L20:L35) -> 33386 | M36: =SUM(M20:M35) -> 0 | N36: =SUM(N20:N35) -> 567705.6 | ... Q36: =SUM(Q20:Q35) -> 183378

Sheet mobilenetv1
A1: MobileNetV1 1.0 (224px, ImageNet-1000)
A2: dw = depthwise 3x3 (cols=9, one filter/channel); pw = pointwise 1x1. Total ~4.21M params.
A4: Tensor kind | B4: Count | C4: Rows (out) | D4: Cols (in) | E4: Params
A5: conv3x3 3->32 s2 | B5: 1 | C5: 32 | D5: 27 | E5: =B5*C5*D5 -> 864
A6: b1 dw 32 (112x112) | B6: 1 | C6: 32 | D6: 9 | E6: =B6*C6*D6 -> 288 | I6: test run results in the sim | J6: rel_L2 error | K6: KL divergence
A7: b1 pw 32->64 | B7: 1 | C7: 64 | D7: 32 | E7: =B7*C7*D7 -> 2048 | I7: noiseless | J7: 0.0112 | K7: 7e-05
A8: b2 dw 64 (56x56) | B8: 1 | C8: 64 | D8: 9 | E8: =B8*C8*D8 -> 576 | I8: with noise | J8: 1.1459±0.2205 | K8: 0.27767±0.07489
A9: b2 pw 64->128 | B9: 1 | C9: 128 | D9: 64 | E9: =B9*C9*D9 -> 8192
A10: b3 dw 128 (56x56) | B10: 1 | C10: 128 | D10: 9 | E10: =B10*C10*D10 -> 1152
A11: b3 pw 128->128 | B11: 1 | C11: 128 | D11: 128 | E11: =B11*C11*D11 -> 16384
A12: b4 dw 128 (28x28) | B12: 1 | C12: 128 | D12: 9 | E12: =B12*C12*D12 -> 1152
A13: b4 pw 128->256 | B13: 1 | C13: 256 | D13: 128 | E13: =B13*C13*D13 -> 32768
A14: b5 dw 256 (28x28) | B14: 1 | C14: 256 | D14: 9 | E14: =B14*C14*D14 -> 2304
A15: b5 pw 256->256 | B15: 1 | C15: 256 | D15: 256 | E15: =B15*C15*D15 -> 65536
A16: b6 dw 256 (14x14) | B16: 1 | C16: 256 | D16: 9 | E16: =B16*C16*D16 -> 2304
A17: b6 pw 256->512 | B17: 1 | C17: 512 | D17: 256 | E17: =B17*C17*D17 -> 131072
A18: b7-b11 dw 512 (14x14) | B18: 5 | C18: 512 | D18: 9 | E18: =B18*C18*D18 -> 23040
A19: b7-b11 pw 512->512 | B19: 5 | C19: 512 | D19: 512 | E19: =B19*C19*D19 -> 1310720
A20: b12 dw 512 (7x7) | B20: 1 | C20: 512 | D20: 9 | E20: =B20*C20*D20 -> 4608
... A24: fc (1024->1001) | B24: 1 | C24: 1001 | D24: 1024 | E24: =B24*C24*D24 -> 1025024
A25: TOTAL | E25: =SUM(E5:E24) -> 4210112
A27: weight bit width | B27: 8
A28: slices | B28: =B27/config!$B$3 -> 4
A31: Layer | B31: Kind | C31: Rows | D31: Cols | E31: H | F31: W | G31: Tiles | H31: Params | I31: Channels | J31: Limiter | K31: Bias | L31: Transistors | M31: Subthreshold transistors | N31: Memristors | O31: Capacitors | P31: Diodes | Q31: Wiring
A32: stem 3x3 s2 | B32: conv | C32: 32 | D32: 27 | E32: 112 | F32: 112 | G32: =IF(OR(B32="conv",B32="pw",B32="head",B32="mm"),-INT(-C32/config!$B$2)*-INT(-D32/config!$B$2),IF(B32="dw",1,"")) -> 1 | H32: =IF(OR(B32="conv",B32="pw",B32="head",B32="mm",B32="dw"),C32*D32,"") -> 864 | I32: =IF(OR(B32="conv",B32="pw",B32="head",B32="mm",B32="dw",B32="pool"),C32,"") -> 32 | J32: =IF(OR(B32="conv",B32="pw",B32="mm",B32="dw"),I32*E32*F32,0) -> 401408 | K32: =IF(OR(B32="conv",B32="pw",B32="dw",B32="head"),C32,0) -> 32 | L32: =IF(B32="dw",I32*config!$B$6+config!$B$16*config!$B$5+K32+config!$B$9,IF(B32="pool",I32*2+config!$B$9,IF(B32="dac",C32*config!$B$12,IF(B32="adc",C32*config!$B$13,IF(OR(B32="conv",B32="pw"),G32*config!$B$7+K32+config!$B$9,IF(B32="head",G32*config!$B$7+K32,"")))))) -> 820 | M32: 0 | N32: =IF(OR(B32="conv",B32="pw",B32="head",B32="mm",B32="dw"),H32*2*mobilenetv1!$B$28*(1+config!$B$4),0) -> 8294.4 | O32: =IF(OR(B32="conv",B32="pw",B32="dw",B32="pool"),config!$B$10,IF(B32="adc",C32*config!$B$14,0)) -> 2 | P32: =IF(OR(B32="conv",B32="pw",B32="dw",B32="pool"),J32*2+config!$B$11,0) -> 802817 | Q32: =IF(OR(B32="conv",B32="pw",B32="dw",B32="head"),G32*2*config!$B$2+I32*10,0) -> 448
A33: L0 dw | B33: dw | C33: 32 | D33: 9 | E33: 112 | F33: 112 | G33: =IF(OR(B33="conv",B33="pw",B33="head",B33="mm"),-INT(-C33/config!$B$2)*-INT(-D33/config!$B$2),IF(B33="dw",1,"")) -> 1 | H33: =IF(OR(B33="conv",B33="pw",B33="head",B33="mm",B33="dw"),C33*D33,"") -> 288 | I33: =IF(OR(B33="conv",B33="pw",B33="head",B33="mm",B33="dw",B33="pool"),C33,"") -> 32 | J33: =IF(OR(B33="conv",B33="pw",B33="mm",B33="dw"),I33*E33*F33,0) -> 401408 | K33: =IF(OR(B33="conv",B33="pw",B33="dw",B33="head"),C33,0) -> 32 | L33: =IF(B33="dw",I33*config!$B$6+config!$B$16*config!$B$5+K33+config!$B$9,IF(B33="pool",I33*2+config!$B$9,IF(B33="dac",C33*config!$B$12,IF(B33="adc",C33*config!$B$13,IF(OR(B33="conv",B33="pw"),G33*config!$B$7+K33+config!$B$9,IF(B33="head",G33*config!$B$7+K33,"")))))) -> 390 | M33: 0 | N33: =IF(OR(B33="conv",B33="pw",B33="head",B33="mm",B33="dw"),H33*2*mobilenetv1!$B$28*(1+config!$B$4),0) -> 2764.8 | O33: =IF(OR(B33="conv",B33="pw",B33="dw",B33="pool"),config!$B$10,IF(B33="adc",C33*config!$B$14,0)) -> 2 | P33: =IF(OR(B33="conv",B33="pw",B33="dw",B33="pool"),J33*2+config!$B$11,0) -> 802817 | Q33: =IF(OR(B33="conv",B33="pw",B33="dw",B33="head"),G33*2*config!$B$2+I33*10,0) -> 448
A34: L1 pw | B34: pw | C34: 64 | D34: 32 | E34: 112 | F34: 112 | G34: =IF(OR(B34="conv",B34="pw",B34="head",B34="mm"),-INT(-C34/config!$B$2)*-INT(-D34/config!$B$2),IF(B34="dw",1,"")) -> 1 | H34: =IF(OR(B34="conv",B34="pw",B34="head",B34="mm",B34="dw"),C34*D34,"") -> 2048 | I34: =IF(OR(B34="conv",B34="pw",B34="head",B34="mm",B34="dw",B34="pool"),C34,"") -> 64 | J34: =IF(OR(B34="conv",B34="pw",B34="mm",B34="dw"),I34*E34*F34,0) -> 802816 | K34: =IF(OR(B34="conv",B34="pw",B34="dw",B34="head"),C34,0) -> 64 | L34: =IF(B34="dw",I34*config!$B$6+config!$B$16*config!$B$5+K34+config!$B$9,IF(B34="pool",I34*2+config!$B$9,IF(B34="dac",C34*config!$B$12,IF(B34="adc",C34*config!$B$13,IF(OR(B34="conv",B34="pw"),G34*config!$B$7+K34+config!$B$9,IF(B34="head",G34*config!$B$7+K34,"")))))) -> 852 | M34: 0 | N34: =IF(OR(B34="conv",B34="pw",B34="head",B34="mm",B34="dw"),H34*2*mobilenetv1!$B$28*(1+config!$B$4),0) -> 19660.8 | O34: =IF(OR(B34="conv",B34="pw",B34="dw",B34="pool"),config!$B$10,IF(B34="adc",C34*config!$B$14,0)) -> 2 | P34: =IF(OR(B34="conv",B34="pw",B34="dw",B34="pool"),J34*2+config!$B$11,0) -> 1605633 | Q34: =IF(OR(B34="conv",B34="pw",B34="dw",B34="head"),G34*2*config!$B$2+I34*10,0) -> 768
A35: L2 dw s2 | B35: dw | C35: 64 | D35: 9 | E35: 56 | F35: 56 | G35: =IF(OR(B35="conv",B35="pw",B35="head",B35="mm"),-INT(-C35/config!$B$2)*-INT(-D35/config!$B$2),IF(B35="dw",1,"")) -> 1 | H35: =IF(OR(B35="conv",B35="pw",B35="head",B35="mm",B35="dw"),C35*D35,"") -> 576 | I35: =IF(OR(B35="conv",B35="pw",B35="head",B35="mm",B35="dw",B35="pool"),C35,"") -> 64 | J35: =IF(OR(B35="conv",B35="pw",B35="mm",B35="dw"),I35*E35*F35,0) -> 200704 | K35: =IF(OR(B35="conv",B35="pw",B35="dw",B35="head"),C35,0) -> 64 | L35: =IF(B35="dw",I35*config!$B$6+config!$B$16*config!$B$5+K35+config!$B$9,IF(B35="pool",I35*2+config!$B$9,IF(B35="dac",C35*config!$B$12,IF(B35="adc",C35*config!$B$13,IF(OR(B35="conv",B35="pw"),G35*config!$B$7+K35+config!$B$9,IF(B35="head",G35*config!$B$7+K35,"")))))) -> 742 | M35: 0 | N35: =IF(OR(B35="conv",B35="pw",B35="head",B35="mm",B35="dw"),H35*2*mobilenetv1!$B$28*(1+config!$B$4),0) -> 5529.6 | O35: =IF(OR(B35="conv",B35="pw",B35="dw",B35="pool"),config!$B$10,IF(B35="adc",C35*config!$B$14,0)) -> 2 | P35: =IF(OR(B35="conv",B35="pw",B35="dw",B35="pool"),J35*2+config!$B$11,0) -> 401409 | Q35: =IF(OR(B35="conv",B35="pw",B35="dw",B35="head"),G35*2*config!$B$2+I35*10,0) -> 768
A36: L3 pw | B36: pw | C36: 128 | D36: 64 | E36: 56 | F36: 56 | G36: =IF(OR(B36="conv",B36="pw",B36="head",B36="mm"),-INT(-C36/config!$B$2)*-INT(-D36/config!$B$2),IF(B36="dw",1,"")) -> 2 | H36: =IF(OR(B36="conv",B36="pw",B36="head",B36="mm",B36="dw"),C36*D36,"") -> 8192 | I36: =IF(OR(B36="conv",B36="pw",B36="head",B36="mm",B36="dw",B36="pool"),C36,"") -> 128 | J36: =IF(OR(B36="conv",B36="pw",B36="mm",B36="dw"),I36*E36*F36,0) -> 401408 | K36: =IF(OR(B36="conv",B36="pw",B36="dw",B36="head"),C36,0) -> 128 | L36: =IF(B36="dw",I36*config!$B$6+config!$B$16*config!$B$5+K36+config!$B$9,IF(B36="pool",I36*2+config!$B$9,IF(B36="dac",C36*config!$B$12,IF(B36="adc",C36*config!$B$13,IF(OR(B36="conv",B36="pw"),G36*config!$B$7+K36+config!$B$9,IF(B36="head",G36*config!$B$7+K36,"")))))) -> 1684 | M36: 0 | N36: =IF(OR(B36="conv",B36="pw",B36="head",B36="mm",B36="dw"),H36*2*mobilenetv1!$B$28*(1+config!$B$4),0) -> 78643.2 | O36: =IF(OR(B36="conv",B36="pw",B36="dw",B36="pool"),config!$B$10,IF(B36="adc",C36*config!$B$14,0)) -> 2 | P36: =IF(OR(B36="conv",B36="pw",B36="dw",B36="pool"),J36*2+config!$B$11,0) -> 802817 | Q36: =IF(OR(B36="conv",B36="pw",B36="dw",B36="head"),G36*2*config!$B$2+I36*10,0) -> 1536
A37: L4 dw | B37: dw | C37: 128 | D37: 9 | E37: 56 | F37: 56 | G37: =IF(OR(B37="conv",B37="pw",B37="head",B37="mm"),-INT(-C37/config!$B$2)*-INT(-D37/config!$B$2),IF(B37="dw",1,"")) -> 1 | H37: =IF(OR(B37="conv",B37="pw",B37="head",B37="mm",B37="dw"),C37*D37,"") -> 1152 | I37: =IF(OR(B37="conv",B37="pw",B37="head",B37="mm",B37="dw",B37="pool"),C37,"") -> 128 | J37: =IF(OR(B37="conv",B37="pw",B37="mm",B37="dw"),I37*E37*F37,0) -> 401408 | K37: =IF(OR(B37="conv",B37="pw",B37="dw",B37="head"),C37,0) -> 128 | L37: =IF(B37="dw",I37*config!$B$6+config!$B$16*config!$B$5+K37+config!$B$9,IF(B37="pool",I37*2+config!$B$9,IF(B37="dac",C37*config!$B$12,IF(B37="adc",C37*config!$B$13,IF(OR(B37="conv",B37="pw"),G37*config!$B$7+K37+config!$B$9,IF(B37="head",G37*config!$B$7+K37,"")))))) -> 1446 | M37: 0 | N37: =IF(OR(B37="conv",B37="pw",B37="head",B37="mm",B37="dw"),H37*2*mobilenetv1!$B$28*(1+config!$B$4),0) -> 11059.2 | O37: =IF(OR(B37="conv",B37="pw",B37="dw",B37="pool"),config!$B$10,IF(B37="adc",C37*config!$B$14,0)) -> 2 | P37: =IF(OR(B37="conv",B37="pw",B37="dw",B37="pool"),J37*2+config!$B$11,0) -> 802817 | Q37: =IF(OR(B37="conv",B37="pw",B37="dw",B37="head"),G37*2*config!$B$2+I37*10,0) -> 1408
A38: L5 pw | B38: pw | C38: 128 | D38: 128 | E38: 56 | F38: 56 | G38: =IF(OR(B38="conv",B38="pw",B38="head",B38="mm"),-INT(-C38/config!$B$2)*-INT(-D38/config!$B$2),IF(B38="dw",1,"")) -> 4 | H38: =IF(OR(B38="conv",B38="pw",B38="head",B38="mm",B38="dw"),C38*D38,"") -> 16384 | I38: =IF(OR(B38="conv",B38="pw",B38="head",B38="mm",B38="dw",B38="pool"),C38,"") -> 128 | J38: =IF(OR(B38="conv",B38="pw",B38="mm",B38="dw"),I38*E38*F38,0) -> 401408 | K38: =IF(OR(B38="conv",B38="pw",B38="dw",B38="head"),C38,0) -> 128 | L38: =IF(B38="dw",I38*config!$B$6+config!$B$16*config!$B$5+K38+config!$B$9,IF(B38="pool",I38*2+config!$B$9,IF(B38="dac",C38*config!$B$12,IF(B38="adc",C38*config!$B$13,IF(OR(B38="conv",B38="pw"),G38*config!$B$7+K38+config!$B$9,IF(B38="head",G38*config!$B$7+K38,"")))))) -> 3220 | M38: 0 | N38: =IF(OR(B38="conv",B38="pw",B38="head",B38="mm",B38="dw"),H38*2*mobilenetv1!$B$28*(1+config!$B$4),0) -> 157286.4 | O38: =IF(OR(B38="conv",B38="pw",B38="dw",B38="pool"),config!$B$10,IF(B38="adc",C38*config!$B$14,0)) -> 2 | P38: =IF(OR(B38="conv",B38="pw",B38="dw",B38="pool"),J38*2+config!$B$11,0) -> 802817 | Q38: =IF(OR(B38="conv",B38="pw",B38="dw",B38="head"),G38*2*config!$B$2+I38*10,0) -> 1792
A39: L6 dw s2 | B39: dw | C39: 128 | D39: 9 | E39: 28 | F39: 28 | G39: =IF(OR(B39="conv",B39="pw",B39="head",B39="mm"),-INT(-C39/config!$B$2)*-INT(-D39/config!$B$2),IF(B39="dw",1,"")) -> 1 | H39: =IF(OR(B39="conv",B39="pw",B39="head",B39="mm",B39="dw"),C39*D39,"") -> 1152 | I39: =IF(OR(B39="conv",B39="pw",B39="head",B39="mm",B39="dw",B39="pool"),C39,"") -> 128 | J39: =IF(OR(B39="conv",B39="pw",B39="mm",B39="dw"),I39*E39*F39,0) -> 100352 | K39: =IF(OR(B39="conv",B39="pw",B39="dw",B39="head"),C39,0) -> 128 | L39: =IF(B39="dw",I39*config!$B$6+config!$B$16*config!$B$5+K39+config!$B$9,IF(B39="pool",I39*2+config!$B$9,IF(B39="dac",C39*config!$B$12,IF(B39="adc",C39*config!$B$13,IF(OR(B39="conv",B39="pw"),G39*config!$B$7+K39+config!$B$9,IF(B39="head",G39*config!$B$7+K39,"")))))) -> 1446 | M39: 0 | N39: =IF(OR(B39="conv",B39="pw",B39="head",B39="mm",B39="dw"),H39*2*mobilenetv1!$B$28*(1+config!$B$4),0) -> 11059.2 | O39: =IF(OR(B39="conv",B39="pw",B39="dw",B39="pool"),config!$B$10,IF(B39="adc",C39*config!$B$14,0)) -> 2 | P39: =IF(OR(B39="conv",B39="pw",B39="dw",B39="pool"),J39*2+config!$B$11,0) -> 200705 | Q39: =IF(OR(B39="conv",B39="pw",B39="dw",B39="head"),G39*2*config!$B$2+I39*10,0) -> 1408
A40: L7 pw | B40: pw | C40: 256 | D40: 128 | E40: 28 | F40: 28 | G40: =IF(OR(B40="conv",B40="pw",B40="head",B40="mm"),-INT(-C40/config!$B$2)*-INT(-D40/config!$B$2),IF(B40="dw",1,"")) -> 8 | H40: =IF(OR(B40="conv",B40="pw",B40="head",B40="mm",B40="dw"),C40*D40,"") -> 32768 | I40: =IF(OR(B40="conv",B40="pw",B40="head",B40="mm",B40="dw",B40="pool"),C40,"") -> 256 | J40: =IF(OR(B40="conv",B40="pw",B40="mm",B40="dw"),I40*E40*F40,0) -> 200704 | K40: =IF(OR(B40="conv",B40="pw",B40="dw",B40="head"),C40,0) -> 256 | L40: =IF(B40="dw",I40*config!$B$6+config!$B$16*config!$B$5+K40+config!$B$9,IF(B40="pool",I40*2+config!$B$9,IF(B40="dac",C40*config!$B$12,IF(B40="adc",C40*config!$B$13,IF(OR(B40="conv",B40="pw"),G40*config!$B$7+K40+config!$B$9,IF(B40="head",G40*config!$B$7+K40,"")))))) -> 6420 | M40: 0 | N40: =IF(OR(B40="conv",B40="pw",B40="head",B40="mm",B40="dw"),H40*2*mobilenetv1!$B$28*(1+config!$B$4),0) -> 314572.8 | O40: =IF(OR(B40="conv",B40="pw",B40="dw",B40="pool"),config!$B$10,IF(B40="adc",C40*config!$B$14,0)) -> 2 | P40: =IF(OR(B40="conv",B40="pw",B40="dw",B40="pool"),J40*2+config!$B$11,0) -> 401409 | Q40: =IF(OR(B40="conv",B40="pw",B40="dw",B40="head"),G40*2*config!$B$2+I40*10,0) -> 3584
A41: L8 dw | B41: dw | C41: 256 | D41: 9 | E41: 28 | F41: 28 | G41: =IF(OR(B41="conv",B41="pw",B41="head",B41="mm"),-INT(-C41/config!$B$2)*-INT(-D41/config!$B$2),IF(B41="dw",1,"")) -> 1 | H41: =IF(OR(B41="conv",B41="pw",B41="head",B41="mm",B41="dw"),C41*D41,"") -> 2304 | I41: =IF(OR(B41="conv",B41="pw",B41="head",B41="mm",B41="dw",B41="pool"),C41,"") -> 256 | J41: =IF(OR(B41="conv",B41="pw",B41="mm",B41="dw"),I41*E41*F41,0) -> 200704 | K41: =IF(OR(B41="conv",B41="pw",B41="dw",B41="head"),C41,0) -> 256 | L41: =IF(B41="dw",I41*config!$B$6+config!$B$16*config!$B$5+K41+config!$B$9,IF(B41="pool",I41*2+config!$B$9,IF(B41="dac",C41*config!$B$12,IF(B41="adc",C41*config!$B$13,IF(OR(B41="conv",B41="pw"),G41*config!$B$7+K41+config!$B$9,IF(B41="head",G41*config!$B$7+K41,"")))))) -> 2854 | M41: 0 | N41: =IF(OR(B41="conv",B41="pw",B41="head",B41="mm",B41="dw"),H41*2*mobilenetv1!$B$28*(1+config!$B$4),0) -> 22118.4 | O41: =IF(OR(B41="conv",B41="pw",B41="dw",B41="pool"),config!$B$10,IF(B41="adc",C41*config!$B$14,0)) -> 2 | P41: =IF(OR(B41="conv",B41="pw",B41="dw",B41="pool"),J41*2+config!$B$11,0) -> 401409 | Q41: =IF(OR(B41="conv",B41="pw",B41="dw",B41="head"),G41*2*config!$B$2+I41*10,0) -> 2688
A42: L9 pw | B42: pw | C42: 256 | D42: 256 | E42: 28 | F42: 28 | G42: =IF(OR(B42="conv",B42="pw",B42="head",B42="mm"),-INT(-C42/config!$B$2)*-INT(-D42/config!$B$2),IF(B42="dw",1,"")) -> 16 | H42: =IF(OR(B42="conv",B42="pw",B42="head",B42="mm",B42="dw"),C42*D42,"") -> 65536 | I42: =IF(OR(B42="conv",B42="pw",B42="head",B42="mm",B42="dw",B42="pool"),C42,"") -> 256 | J42: =IF(OR(B42="conv",B42="pw",B42="mm",B42="dw"),I42*E42*F42,0) -> 200704 | K42: =IF(OR(B42="conv",B42="pw",B42="dw",B42="head"),C42,0) -> 256 | L42: =IF(B42="dw",I42*config!$B$6+config!$B$16*config!$B$5+K42+config!$B$9,IF(B42="pool",I42*2+config!$B$9,IF(B42="dac",C42*config!$B$12,IF(B42="adc",C42*config!$B$13,IF(OR(B42="conv",B42="pw"),G42*config!$B$7+K42+config!$B$9,IF(B42="head",G42*config!$B$7+K42,"")))))) -> 12564 | M42: 0 | N42: =IF(OR(B42="conv",B42="pw",B42="head",B42="mm",B42="dw"),H42*2*mobilenetv1!$B$28*(1+config!$B$4),0) -> 629145.6 | O42: =IF(OR(B42="conv",B42="pw",B42="dw",B42="pool"),config!$B$10,IF(B42="adc",C42*config!$B$14,0)) -> 2 | P42: =IF(OR(B42="conv",B42="pw",B42="dw",B42="pool"),J42*2+config!$B$11,0) -> 401409 | Q42: =IF(OR(B42="conv",B42="pw",B42="dw",B42="head"),G42*2*config!$B$2+I42*10,0) -> 4608
A43: L10 dw s2 | B43: dw | C43: 256 | D43: 9 | E43: 14 | F43: 14 | G43: =IF(OR(B43="conv",B43="pw",B43="head",B43="mm"),-INT(-C43/config!$B$2)*-INT(-D43/config!$B$2),IF(B43="dw",1,"")) -> 1 | H43: =IF(OR(B43="conv",B43="pw",B43="head",B43="mm",B43="dw"),C43*D43,"") -> 2304 | I43: =IF(OR(B43="conv",B43="pw",B43="head",B43="mm",B43="dw",B43="pool"),C43,"") -> 256 | J43: =IF(OR(B43="conv",B43="pw",B43="mm",B43="dw"),I43*E43*F43,0) -> 50176 | K43: =IF(OR(B43="conv",B43="pw",B43="dw",B43="head"),C43,0) -> 256 | L43: =IF(B43="dw",I43*config!$B$6+config!$B$16*config!$B$5+K43+config!$B$9,IF(B43="pool",I43*2+config!$B$9,IF(B43="dac",C43*config!$B$12,IF(B43="adc",C43*config!$B$13,IF(OR(B43="conv",B43="pw"),G43*config!$B$7+K43+config!$B$9,IF(B43="head",G43*config!$B$7+K43,"")))))) -> 2854 | M43: 0 | N43: =IF(OR(B43="conv",B43="pw",B43="head",B43="mm",B43="dw"),H43*2*mobilenetv1!$B$28*(1+config!$B$4),0) -> 22118.4 | O43: =IF(OR(B43="conv",B43="pw",B43="dw",B43="pool"),config!$B$10,IF(B43="adc",C43*config!$B$14,0)) -> 2 | P43: =IF(OR(B43="conv",B43="pw",B43="dw",B43="pool"),J43*2+config!$B$11,0) -> 100353 | Q43: =IF(OR(B43="conv",B43="pw",B43="dw",B43="head"),G43*2*config!$B$2+I43*10,0) -> 2688
... A58: L25 pw | B58: pw | C58: 1024 | D58: 1024 | E58: 7 | F58: 7 | G58: =IF(OR(B58="conv",B58="pw",B58="head",B58="mm"),-INT(-C58/config!$B$2)*-INT(-D58/config!$B$2),IF(B58="dw",1,"")) -> 256 | H58: =IF(OR(B58="conv",B58="pw",B58="head",B58="mm",B58="dw"),C58*D58,"") -> 1048576 | I58: =IF(OR(B58="conv",B58="pw",B58="head",B58="mm",B58="dw",B58="pool"),C58,"") -> 1024 | J58: =IF(OR(B58="conv",B58="pw",B58="mm",B58="dw"),I58*E58*F58,0) -> 50176 | K58: =IF(OR(B58="conv",B58="pw",B58="dw",B58="head"),C58,0) -> 1024 | L58: =IF(B58="dw",I58*config!$B$6+config!$B$16*config!$B$5+K58+config!$B$9,IF(B58="pool",I58*2+config!$B$9,IF(B58="dac",C58*config!$B$12,IF(B58="adc",C58*config!$B$13,IF(OR(B58="conv",B58="pw"),G58*config!$B$7+K58+config!$B$9,IF(B58="head",G58*config!$B$7+K58,"")))))) -> 197652 | M58: 0 | N58: =IF(OR(B58="conv",B58="pw",B58="head",B58="mm",B58="dw"),H58*2*mobilenetv1!$B$28*(1+config!$B$4),0) -> 10066330 | O58: =IF(OR(B58="conv",B58="pw",B58="dw",B58="pool"),config!$B$10,IF(B58="adc",C58*config!$B$14,0)) -> 2 | P58: =IF(OR(B58="conv",B58="pw",B58="dw",B58="pool"),J58*2+config!$B$11,0) -> 100353 | Q58: =IF(OR(B58="conv",B58="pw",B58="dw",B58="head"),G58*2*config!$B$2+I58*10,0) -> 43008
A59: AvgPool 49:1 | B59: pool | C59: 1024 | E59: 1 | F59: 1 | G59: =IF(OR(B59="conv",B59="pw",B59="head",B59="mm"),-INT(-C59/config!$B$2)*-INT(-D59/config!$B$2),IF(B59="dw",1,"")) | H59: =IF(OR(B59="conv",B59="pw",B59="head",B59="mm",B59="dw"),C59*D59,"") | I59: =IF(OR(B59="conv",B59="pw",B59="head",B59="mm",B59="dw",B59="pool"),C59,"") -> 1024 | J59: =IF(OR(B59="conv",B59="pw",B59="mm",B59="dw"),I59*E59*F59,0) -> 0 | K59: =IF(OR(B59="conv",B59="pw",B59="dw",B59="head"),C59,0) -> 0 | L59: =IF(B59="dw",I59*config!$B$6+config!$B$16*config!$B$5+K59+config!$B$9,IF(B59="pool",I59*2+config!$B$9,IF(B59="dac",C59*config!$B$12,IF(B59="adc",C59*config!$B$13,IF(OR(B59="conv",B59="pw"),G59*config!$B$7+K59+config!$B$9,IF(B59="head",G59*config!$B$7+K59,"")))))) -> 2068 | M59: 0 | N59: =IF(OR(B59="conv",B59="pw",B59="head",B59="mm",B59="dw"),H59*2*mobilenetv1!$B$28*(1+config!$B$4),0) -> 0 | O59: =IF(OR(B59="conv",B59="pw",B59="dw",B59="pool"),config!$B$10,IF(B59="adc",C59*config!$B$14,0)) -> 2 | P59: =IF(OR(B59="conv",B59="pw",B59="dw",B59="pool"),J59*2+config!$B$11,0) -> 1 | Q59: =IF(OR(B59="conv",B59="pw",B59="dw",B59="head"),G59*2*config!$B$2+I59*10,0) -> 0
A60: head (no act) | B60: head | C60: 1001 | D60: 1024 | E60: 1 | F60: 1 | G60: =IF(OR(B60="conv",B60="pw",B60="head",B60="mm"),-INT(-C60/config!$B$2)*-INT(-D60/config!$B$2),IF(B60="dw",1,"")) -> 256 | H60: =IF(OR(B60="conv",B60="pw",B60="head",B60="mm",B60="dw"),C60*D60,"") -> 1025024 | I60: =IF(OR(B60="conv",B60="pw",B60="head",B60="mm",B60="dw",B60="pool"),C60,"") -> 1001 | J60: =IF(OR(B60="conv",B60="pw",B60="mm",B60="dw"),I60*E60*F60,0) -> 0 | K60: =IF(OR(B60="conv",B60="pw",B60="dw",B60="head"),C60,0) -> 1001 | L60: =IF(B60="dw",I60*config!$B$6+config!$B$16*config!$B$5+K60+config!$B$9,IF(B60="pool",I60*2+config!$B$9,IF(B60="dac",C60*config!$B$12,IF(B60="adc",C60*config!$B$13,IF(OR(B60="conv",B60="pw"),G60*config!$B$7+K60+config!$B$9,IF(B60="head",G60*config!$B$7+K60,"")))))) -> 197609 | M60: 0 | N60: =IF(OR(B60="conv",B60="pw",B60="head",B60="mm",B60="dw"),H60*2*mobilenetv1!$B$28*(1+config!$B$4),0) -> 9840230.4 | O60: =IF(OR(B60="conv",B60="pw",B60="dw",B60="pool"),config!$B$10,IF(B60="adc",C60*config!$B$14,0)) -> 0 | P60: =IF(OR(B60="conv",B60="pw",B60="dw",B60="pool"),J60*2+config!$B$11,0) -> 0 | Q60: =IF(OR(B60="conv",B60="pw",B60="dw",B60="head"),G60*2*config!$B$2+I60*10,0) -> 42778
A61: DAC(8) | B61: dac | C61: 150528 | G61: =IF(OR(B61="conv",B61="pw",B61="head",B61="mm"),-INT(-C61/config!$B$2)*-INT(-D61/config!$B$2),IF(B61="dw",1,"")) | H61: =IF(OR(B61="conv",B61="pw",B61="head",B61="mm",B61="dw"),C61*D61,"") | I61: =IF(OR(B61="conv",B61="pw",B61="head",B61="mm",B61="dw",B61="pool"),C61,"") | J61: =IF(OR(B61="conv",B61="pw",B61="mm",B61="dw"),I61*E61*F61,0) -> 0 | K61: =IF(OR(B61="conv",B61="pw",B61="dw",B61="head"),C61,0) -> 0 | L61: =IF(B61="dw",I61*config!$B$6+config!$B$16*config!$B$5+K61+config!$B$9,IF(B61="pool",I61*2+config!$B$9,IF(B61="dac",C61*config!$B$12,IF(B61="adc",C61*config!$B$13,IF(OR(B61="conv",B61="pw"),G61*config!$B$7+K61+config!$B$9,IF(B61="head",G61*config!$B$7+K61,"")))))) -> 1204224 | M61: 0 | N61: =IF(OR(B61="conv",B61="pw",B61="head",B61="mm",B61="dw"),H61*2*mobilenetv1!$B$28*(1+config!$B$4),0) -> 0 | O61: =IF(OR(B61="conv",B61="pw",B61="dw",B61="pool"),config!$B$10,IF(B61="adc",C61*config!$B$14,0)) -> 0 | P61: =IF(OR(B61="conv",B61="pw",B61="dw",B61="pool"),J61*2+config!$B$11,0) -> 0 | Q61: =IF(OR(B61="conv",B61="pw",B61="dw",B61="head"),G61*2*config!$B$2+I61*10,0) -> 0
...

Sheet qwen_block
A1: Qwen3.8-27B
A2: Input – dynamic + kv-cache, would use paged attention aligned to crossbar tile size
A4: Tensor kind | B4: Count | C4: Rows (out) | D4: Cols (in) | E4: Params
A5: token_embd.weight | B5: 1 | C5: 248320 | D5: 5120 | E5: =B5*C5*D5 -> 1271398400
A6: output.weight (lm_head) | B6: 1 | C6: 248320 | D6: 5120 | E6: =B6*C6*D6 -> 1271398400 | I6: test run results in the sim | J6: rel_L2 error | K6: r (correlation)
A7: attn_qkv (linear attn) | B7: 48 | C7: 10240 | D7: 5120 | E7: =B7*C7*D7 -> 2516582400 | I7: orig ideal-vs-golden | J7: 0.0005 | K7: 1
A8: attn_gate (linear attn) | B8: 48 | C8: 6144 | D8: 5120 | E8: =B8*C8*D8 -> 1509949440 | I8: orig noiseless | J8: 0.0355 | K8: 0.9994
A9: ssm_alpha (linear attn) | B9: 48 | C9: 48 | D9: 5120 | E9: =B9*C9*D9 -> 11796480 | I9: orig default | J9: 1.2213±0.5090 | K9: 0.4561±0.2231
A10: ssm_beta (linear attn) | B10: 48 | C10: 48 | D10: 5120 | E10: =B10*C10*D10 -> 11796480 | I10: tuned ideal-vs-golden | J10: 0.2952 | K10: 0.9641
A11: ssm_out (linear attn) | B11: 48 | C11: 5120 | D11: 6144 | E11: =B11*C11*D11 -> 1509949440 | I11: tuned noiseless | J11: 0.2981 | K11: 0.9623
A12: attn_q (dense attn) | B12: 17 | C12: 12288 | D12: 5120 | E12: =B12*C12*D12 -> 1069547520 | I12: tuned default | J12: 0.9078±0.3368 | K12: 0.6276±0.1496
A13: attn_k (dense attn) | B13: 17 | C13: 1024 | D13: 5120 | E13: =B13*C13*D13 -> 89128960
A14: attn_v (dense attn) | B14: 17 | C14: 1024 | D14: 5120 | E14: =B14*C14*D14 -> 89128960
A15: attn_output (dense attn) | B15: 17 | C15: 5120 | D15: 6144 | E15: =B15*C15*D15 -> 534773760
A16: ffn_gate | B16: 65 | C16: 17408 | D16: 5120 | E16: =B16*C16*D16 -> 5793382400
A17: ffn_up | B17: 65 | C17: 17408 | D17: 5120 | E17: =B17*C17*D17 -> 5793382400
A18: ffn_down | B18: 65 | C18: 5120 | D18: 17408 | E18: =B18*C18*D18 -> 5793382400
A19: nextn.eh_proj (MTP) | B19: 1 | C19: 5120 | D19: 10240 | E19: =B19*C19*D19 -> 52428800
A20: TOTAL | E20: =SUM(E5:E19) -> 27318026240
A22: S_BUS | B22: 16
A23: S_LIVE | B23: 6
A24: # heads | B24: 48
A25: head dimension | B25: 128
A26: model dimension | B26: 5120
A27: weight bit width | B27: 16
A28: slices | B28: =B27/config!$B$3 -> 8
A30: Qwen3.8-27B linear-attn block - ONE block, 16-bit weights finetuned
A31: Layer | B31: Kind | C31: Rows | D31: Cols | E31: H | F31: W | G31: Tiles | H31: Params | I31: Channels | J31: Limiter | K31: Bias | L31: Transistors | M31: Subthreshold transistors | N31: Memristors | O31: Capacitors | P31: Diodes | Q31: Wiring
A32: w_qkv | B32: mm | C32: =2*qwen_block!$B$26 -> 10240 | D32: =qwen_block!$B$26 -> 5120 | G32: =IF(OR(B32="conv",B32="pw",B32="head",B32="mm"),-INT(-C32/config!$B$2)*-INT(-D32/config!$B$2),IF(B32="dw",1,"")) -> 12800 | H32: =IF(OR(B32="conv",B32="pw",B32="head",B32="mm",B32="dw"),C32*D32,"") -> 52428800 | I32: =IF(OR(B32="conv",B32="pw",B32="head",B32="mm",B32="dw"),C32,"") -> 10240 | J32: 0 | K32: 0 | L32: =IF(B32="mm",G32*config!$B$7,IF(B32="dac",C32*config!$B$12,IF(B32="adc",C32*config!$B$13,""))) -> 9830400 | M32: 0 | N32: =IF(OR(B32="conv",B32="pw",B32="head",B32="mm",B32="dw"),H32*2*qwen_block!$B$28*(1+config!$B$4),0) -> 1006632960 | O32: =IF(B32="adc",C32*config!$B$14,0) -> 0 | P32: 0 | Q32: =IF(OR(B32="mm",B32="head",B32="conv",B32="pw",B32="dw",B32="dwca"),G32*2*config!$B$2+C32*config!$B$24,0) -> 1740800
A33: w_z | B33: mm | C33: =qwen_block!$B$24*qwen_block!$B$25 -> 6144 | D33: =qwen_block!$B$26 -> 5120 | G33: =IF(OR(B33="conv",B33="pw",B33="head",B33="mm"),-INT(-C33/config!$B$2)*-INT(-D33/config!$B$2),IF(B33="dw",1,"")) -> 7680 | H33: =IF(OR(B33="conv",B33="pw",B33="head",B33="mm",B33="dw"),C33*D33,"") -> 31457280 | I33: =IF(OR(B33="conv",B33="pw",B33="head",B33="mm",B33="dw"),C33,"") -> 6144 | J33: 0 | K33: 0 | L33: =IF(B33="mm",G33*config!$B$7,IF(B33="dac",C33*config!$B$12,IF(B33="adc",C33*config!$B$13,""))) -> 5898240 | M33: 0 | N33: =IF(OR(B33="conv",B33="pw",B33="head",B33="mm",B33="dw"),H33*2*qwen_block!$B$28*(1+config!$B$4),0) -> 603979776 | O33: =IF(B33="adc",C33*config!$B$14,0) -> 0 | P33: 0 | Q33: =IF(OR(B33="mm",B33="head",B33="conv",B33="pw",B33="dw",B33="dwca"),G33*2*config!$B$2+C33*config!$B$24,0) -> 1044480
A34: w_b | B34: mm | C34: =qwen_block!$B$24 -> 48 | D34: =qwen_block!$B$26 -> 5120 | G34: =IF(OR(B34="conv",B34="pw",B34="head",B34="mm"),-INT(-C34/config!$B$2)*-INT(-D34/config!$B$2),IF(B34="dw",1,"")) -> 80 | H34: =IF(OR(B34="conv",B34="pw",B34="head",B34="mm",B34="dw"),C34*D34,"") -> 245760 | I34: =IF(OR(B34="conv",B34="pw",B34="head",B34="mm",B34="dw"),C34,"") -> 48 | J34: 0 | K34: 0 | L34: =IF(B34="mm",G34*config!$B$7,IF(B34="dac",C34*config!$B$12,IF(B34="adc",C34*config!$B$13,""))) -> 61440 | M34: 0 | N34: =IF(OR(B34="conv",B34="pw",B34="head",B34="mm",B34="dw"),H34*2*qwen_block!$B$28*(1+config!$B$4),0) -> 4718592 | O34: =IF(B34="adc",C34*config!$B$14,0) -> 0 | P34: 0 | Q34: =IF(OR(B34="mm",B34="head",B34="conv",B34="pw",B34="dw",B34="dwca"),G34*2*config!$B$2+C34*config!$B$24,0) -> 10720
A35: w_a | B35: mm | C35: =qwen_block!$B$24 -> 48 | D35: =qwen_block!$B$26 -> 5120 | G35: =IF(OR(B35="conv",B35="pw",B35="head",B35="mm"),-INT(-C35/config!$B$2)*-INT(-D35/config!$B$2),IF(B35="dw",1,"")) -> 80 | H35: =IF(OR(B35="conv",B35="pw",B35="head",B35="mm",B35="dw"),C35*D35,"") -> 245760 | I35: =IF(OR(B35="conv",B35="pw",B35="head",B35="mm",B35="dw"),C35,"") -> 48 | J35: 0 | K35: 0 | L35: =IF(B35="mm",G35*config!$B$7,IF(B35="dac",C35*config!$B$12,IF(B35="adc",C35*config!$B$13,""))) -> 61440 | M35: 0 | N35: =IF(OR(B35="conv",B35="pw",B35="head",B35="mm",B35="dw"),H35*2*qwen_block!$B$28*(1+config!$B$4),0) -> 4718592 | O35: =IF(B35="adc",C35*config!$B$14,0) -> 0 | P35: 0 | Q35: =IF(OR(B35="mm",B35="head",B35="conv",B35="pw",B35="dw",B35="dwca"),G35*2*config!$B$2+C35*config!$B$24,0) -> 10720
A36: w_o | B36: mm | C36: =qwen_block!$B$26 -> 5120 | D36: =qwen_block!$B$24*qwen_block!$B$25 -> 6144 | G36: =IF(OR(B36="conv",B36="pw",B36="head",B36="mm"),-INT(-C36/config!$B$2)*-INT(-D36/config!$B$2),IF(B36="dw",1,"")) -> 7680 | H36: =IF(OR(B36="conv",B36="pw",B36="head",B36="mm",B36="dw"),C36*D36,"") -> 31457280 | I36: =IF(OR(B36="conv",B36="pw",B36="head",B36="mm",B36="dw"),C36,"") -> 5120 | J36: 0 | K36: 0 | L36: =IF(B36="mm",G36*config!$B$7,IF(B36="dac",C36*config!$B$12,IF(B36="adc",C36*config!$B$13,""))) -> 5898240 | M36: 0 | N36: =IF(OR(B36="conv",B36="pw",B36="head",B36="mm",B36="dw"),H36*2*qwen_block!$B$28*(1+config!$B$4),0) -> 603979776 | O36: =IF(B36="adc",C36*config!$B$14,0) -> 0 | P36: 0 | Q36: =IF(OR(B36="mm",B36="head",B36="conv",B36="pw",B36="dw",B36="dwca"),G36*2*config!$B$2+C36*config!$B$24,0) -> 1034240
A37: DWConv ColumnArray (custom, see note) | B37: dwca | C37: 10240 | G37: 160 | H37: =2*qwen_block!$B$26*4 -> 40960 | L37: =C37*config!$B$25+config!$B$26 -> 112678 | N37: =H37*2*qwen_block!$B$28*(1+config!$B$4) -> 786432 | Q37: =IF(OR(B37="mm",B37="head",B37="conv",B37="pw",B37="dw",B37="dwca"),G37*2*config!$B$2+C37*config!$B$24,0) -> 122880
A38: DWConv SiLU | B38: kernel | C38: =qwen_block!$B$22*2*qwen_block!$B$26 -> 163840 | D38: 1 | G38: =IF(OR(B38="conv",B38="pw",B38="head",B38="mm"),-INT(-C38/config!$B$2)*-INT(-D38/config!$B$2),IF(B38="dw",1,"")) | H38: =IF(OR(B38="conv",B38="pw",B38="head",B38="mm",B38="dw"),C38*D38,"") | I38: =IF(OR(B38="conv",B38="pw",B38="head",B38="mm",B38="dw"),C38,"") | J38: 0 | K38: 0 | L38: =IF(B38="mm",G38*config!$B$7,IF(B38="dac",C38*config!$B$12,IF(B38="adc",C38*config!$B$13,""))) | M38: =C38*config!$B$22 -> 2457600 | N38: =IF(OR(B38="conv",B38="pw",B38="head",B38="mm",B38="dw"),H38*2*qwen_block!$B$28*(1+config!$B$4),0) -> 0 | O38: =IF(B38="adc",C38*config!$B$14,0) -> 0 | P38: 0 | Q38: =IF(OR(B38="mm",B38="head",B38="conv",B38="pw",B38="dw",B38="dwca"),G38*2*config!$B$2+C38*config!$B$24,0) -> 0
A39: Gate (beta+decay) | B39: kernel | C39: =qwen_block!$B$22*qwen_block!$B$24 -> 768 | D39: 1 | G39: =IF(OR(B39="conv",B39="pw",B39="head",B39="mm"),-INT(-C39/config!$B$2)*-INT(-D39/config!$B$2),IF(B39="dw",1,"")) | H39: =IF(OR(B39="conv",B39="pw",B39="head",B39="mm",B39="dw"),C39*D39,"") | I39: =IF(OR(B39="conv",B39="pw",B39="head",B39="mm",B39="dw"),C39,"") | J39: 0 | K39: 0 | L39: =IF(B39="mm",G39*config!$B$7,IF(B39="dac",C39*config!$B$12,IF(B39="adc",C39*config!$B$13,""))) | M39: =C39*config!$B$21 -> 22272 | N39: =IF(OR(B39="conv",B39="pw",B39="head",B39="mm",B39="dw"),H39*2*qwen_block!$B$28*(1+config!$B$4),0) -> 0 | O39: =IF(B39="adc",C39*config!$B$14,0) -> 0 | P39: 0 | Q39: =IF(OR(B39="mm",B39="head",B39="conv",B39="pw",B39="dw",B39="dwca"),G39*2*config!$B$2+C39*config!$B$24,0) -> 0
A40: L2Norm (q,k) | B40: kernel | C40: =qwen_block!$B$22*qwen_block!$B$24*2 -> 1536 | D40: 1 | G40: =IF(OR(B40="conv",B40="pw",B40="head",B40="mm"),-INT(-C40/config!$B$2)*-INT(-D40/config!$B$2),IF(B40="dw",1,"")) | H40: =IF(OR(B40="conv",B40="pw",B40="head",B40="mm",B40="dw"),C40*D40,"") | I40: =IF(OR(B40="conv",B40="pw",B40="head",B40="mm",B40="dw"),C40,"") | J40: 0 | K40: 0 | L40: =C40*config!$B$20 -> 15360 | M40: =C40*(qwen_block!$B$25*config!$B$17+config!$B$18+config!$B$19) -> 814080 | N40: =IF(OR(B40="conv",B40="pw",B40="head",B40="mm",B40="dw"),H40*2*qwen_block!$B$28*(1+config!$B$4),0) -> 0 | O40: =IF(B40="adc",C40*config!$B$14,0) -> 0 | P40: 0 | Q40: =IF(OR(B40="mm",B40="head",B40="conv",B40="pw",B40="dw",B40="dwca"),G40*2*config!$B$2+C40*config!$B$24,0) -> 0
A41: GDN state (CapArray) | B41: kernel | C41: =qwen_block!$B$24*qwen_block!$B$25*qwen_block!$B$25 -> 786432 | D41: 1 | G41: =IF(OR(B41="conv",B41="pw",B41="head",B41="mm"),-INT(-C41/config!$B$2)*-INT(-D41/config!$B$2),IF(B41="dw",1,"")) | H41: =IF(OR(B41="conv",B41="pw",B41="head",B41="mm",B41="dw"),C41*D41,"") | I41: =IF(OR(B41="conv",B41="pw",B41="head",B41="mm",B41="dw"),C41,"") | J41: 0 | K41: 0 | L41: =C41 -> 786432 | M41: 0 | N41: =IF(OR(B41="conv",B41="pw",B41="head",B41="mm",B41="dw"),H41*2*qwen_block!$B$28*(1+config!$B$4),0) -> 0 | O41: =C41 -> 786432 | P41: 0 | Q41: =IF(OR(B41="mm",B41="head",B41="conv",B41="pw",B41="dw",B41="dwca"),G41*2*config!$B$2+C41*config!$B$24,0) -> 0
A42: Head readout mults | B42: kernel | C42: =qwen_block!$B$22*qwen_block!$B$24*qwen_block!$B$25 -> 98304 | D42: 1 | G42: =IF(OR(B42="conv",B42="pw",B42="head",B42="mm"),-INT(-C42/config!$B$2)*-INT(-D42/config!$B$2),IF(B42="dw",1,"")) | H42: =IF(OR(B42="conv",B42="pw",B42="head",B42="mm",B42="dw"),C42*D42,"") | I42: =IF(OR(B42="conv",B42="pw",B42="head",B42="mm",B42="dw"),C42,"") | J42: 0 | K42: 0 | L42: =IF(B42="mm",G42*config!$B$7,IF(B42="dac",C42*config!$B$12,IF(B42="adc",C42*config!$B$13,""))) | M42: =C42*config!$B$23 -> 983040 | N42: =IF(OR(B42="conv",B42="pw",B42="head",B42="mm",B42="dw"),H42*2*qwen_block!$B$28*(1+config!$B$4),0) -> 0 | O42: =IF(B42="adc",C42*config!$B$14,0) -> 0 | P42: 0 | Q42: =IF(OR(B42="mm",B42="head",B42="conv",B42="pw",B42="dw",B42="dwca"),G42*2*config!$B$2+C42*config!$B$24,0) -> 0
A43: RMSNorm(128) | B43: kernel | C43: =$B$23*$B$24 -> 288 | D43: 1 | G43: =IF(OR(B43="conv",B43="pw",B43="head",B43="mm"),-INT(-C43/config!$B$2)*-INT(-D43/config!$B$2),IF(B43="dw",1,"")) | H43: =IF(OR(B43="conv",B43="pw",B43="head",B43="mm",B43="dw"),C43*D43,"") | I43: =IF(OR(B43="conv",B43="pw",B43="head",B43="mm",B43="dw"),C43,"") | J43: 0 | K43: 0 | L43: =C43*$B$25*config!$B$20 -> 368640 | M43: =C43*(qwen_block!$B$25*config!$B$17+config!$B$18*$B$25+config!$B$19)+C43*qwen_block!$B$25*config!$B$23 -> 887040 | N43: =IF(OR(B43="conv",B43="pw",B43="head",B43="mm",B43="dw"),H43*2*qwen_block!$B$28*(1+config!$B$4),0) -> 0 | O43: =IF(B43="adc",C43*config!$B$14,0) -> 0 | P43: 0 | Q43: =IF(OR(B43="mm",B43="head",B43="conv",B43="pw",B43="dw",B43="dwca"),G43*2*config!$B$2+C43*config!$B$24,0) -> 0
...
